Traceback (most recent call last):
  File "/u/jc4557/COS333_A3/testregdetails.py", line 57, in <module>
    main()
  File "/u/jc4557/COS333_A3/testregdetails.py", line 41, in main
    driver = webdriver.Firefox()
  File "/u/jc4557/.virtualenvs/cos333/lib/python3.10/site-packages/selenium/webdriver/firefox/webdriver.py", line 67, in __init__
    super().__init__(command_executor=executor, options=options)
  File "/u/jc4557/.virtualenvs/cos333/lib/python3.10/site-packages/selenium/webdriver/remote/webdriver.py", line 205, in __init__
    self.start_session(capabilities)
  File "/u/jc4557/.virtualenvs/cos333/lib/python3.10/site-packages/selenium/webdriver/remote/webdriver.py", line 289, in start_session
    response = self.execute(Command.NEW_SESSION, caps)["value"]
  File "/u/jc4557/.virtualenvs/cos333/lib/python3.10/site-packages/selenium/webdriver/remote/webdriver.py", line 344, in execute
    self.error_handler.check_response(response)
  File "/u/jc4557/.virtualenvs/cos333/lib/python3.10/site-packages/selenium/webdriver/remote/errorhandler.py", line 229, in check_response
    raise exception_class(message, screen, stacktrace)
selenium.common.exceptions.WebDriverException: Message: Process unexpectedly closed with status 1

